<?xml version="1.0"?>
<robot name="caato_360Cam" xmlns:xacro="http://ros.org/wiki/xacro">

  <!-- Mod by Tim  -->
    <xacro:include filename="$(find caato_description)/urdf/common_properties.xacro"/>
    <xacro:include filename="$(find caato_description)/urdf/caato_360Cam.gazebo.xacro"/>

    <!-- sensors -->
    <xacro:include filename="$(find realsense2_description)/urdf/_d435.2.urdf.xacro"/>
    <xacro:include filename="$(find realsense2_description)/urdf/_d435.gazebo.xacro"/>
    <xacro:sensor_d435 parent="base_link">
        <origin xyz="-0.35 0 0.38" rpy="0 0 3.14159" />
    </xacro:sensor_d435>   
    
    <xacro:include filename="$(find realsense2_description)/urdf/_d435.front.urdf.xacro"/>
    <xacro:include filename="$(find realsense2_description)/urdf/_d435.front.gazebo.xacro"/>
    <xacro:d435_front parent="base_link">
        <origin xyz="0.35 0 0.38" rpy="0 0 0" />
    </xacro:d435_front> 

    
  <!-- End Mod -->


  <link name="base_link">
    <visual>
      <origin xyz="0 0 0.0625" rpy="0 0 0" />
      <geometry>
        <mesh filename="package://caato_description/meshes/base_link.stl"/>
      </geometry>
      <material name="base_material">
        <color rgba="0.615686 0.811765 0.929412 1.0"/>
      </material>
    </visual>
    <collision>
      <origin xyz="0 0 0.0625" rpy="0 0 0" />
      <geometry>
        <mesh filename="package://caato_description/meshes/base_link.stl"/>
      </geometry>
      <material name="base_material">
        <color rgba="0.615686 0.811765 0.929412 1.0"/>
      </material>
    </collision>
  </link>
  <gazebo reference="base_link">
    <mu1 value="0.0" />
    <mu2 value="0.0" />
    <material>Gazebo/Turquoise</material>
  </gazebo>

  <link name="inertial_link" >
    <inertial>
      <mass value="1" />
      <!-- <origin xyz="&#45;0.00065 &#45;0.085 0.062" /> -->
      <origin xyz="0 -0.085 0.0625" />
      <inertia ixx="0.2" ixy="0" ixz="0" iyy="0.2" iyz="0" izz="1.0296" />
      <origin xyz="0 0 0" rpy="0 0 0"/>
    </inertial>
  </link>

  <joint name="inertial_joint" type="fixed" >
    <orgin xyz="0 0 0" rpy="0 0 0" />
    <parent link="base_link" />
    <child link="inertial_link" />
  </joint>

  <link name="imu_link"/>
  <joint name="imu_joint" type="fixed">
    <origin xyz = "0 0 0.0625" rpy="0 0 0" />
    <parent link="base_link" />
    <child link="imu_link" />
  </joint>

  <link name="hokuyo_laser_scanner_1">
    <visual>
      <origin xyz="0 0 0" rpy="0 0 0" />
      <geometry>
        <mesh filename="package://caato_description/meshes/hokuyo_laser_scanner.stl"/>
      </geometry>
      <material name="hokuyo_laser_scanner_material">
        <color rgba="1 0.643137 0.0313725 1.0"/>
      </material>
    </visual>
    <collision>
      <origin xyz="0 0 0" rpy="0 0 0" />
      <geometry>
        <mesh filename="package://caato_description/meshes/hokuyo_laser_scanner.stl"/>
      </geometry>
      <material name="hokuyo_laser_scanner_material">
        <color rgba="1 0.643137 0.0313725 1.0"/>
      </material>
    </collision>
    <inertial>
      <origin xyz="0 0 0" rpy="0 0 0"/>
      <mass value="0.2" />
      <inertia ixx="0" ixy="0"  ixz="0" iyy="0" iyz="0" izz="0" />
    </inertial>
  </link>
  <gazebo reference="hokuyo_laser_scanner_1">
    <material>Gazebo/Orange</material>
  </gazebo>
  
  <joint name="hokuyo_laser_scanner_1_joint" type="fixed">
    <origin xyz="0.320104 0.330104 0.05225" rpy="3.14159 0 0.785398" />
    <parent link="base_link" />
    <child link="hokuyo_laser_scanner_1" />
    <axis xyz="0 0 1"/>
  </joint>

  <link name="hokuyo_laser_scanner_2">
    <visual>
      <origin xyz="0 0 0" rpy="0 0 0" />
      <geometry>
        <mesh filename="package://caato_description/meshes/hokuyo_laser_scanner.stl"/>
      </geometry>
      <material name="hokuyo_laser_scanner_material">
        <color rgba="1 0.643137 0.0313725 1.0"/>
      </material>
    </visual>
    <collision>
      <origin xyz="0 0 0" rpy="0 0 0" />
      <geometry>
        <mesh filename="package://caato_description/meshes/hokuyo_laser_scanner.stl"/>
      </geometry>
      <material name="hokuyo_laser_scanner_material">
        <color rgba="1 0.643137 0.0313725 1.0"/>
      </material>
    </collision>
    <inertial>
      <origin xyz="0 0 0" rpy="0 0 0"/>
      <mass value="0" />
      <inertia ixx="0" ixy="0"  ixz="0" iyy="0" iyz="0" izz="0" />
    </inertial>
  </link>

  <gazebo reference="hokuyo_laser_scanner_2">
    <material>Gazebo/Orange</material>
  </gazebo>

  <joint name="hokuyo_laser_scanner_2_joint" type="fixed">
    <origin xyz="-0.320104 -0.330104 0.0525" rpy="3.14159 0 -2.355" />
    <parent link="base_link" />
    <child link="hokuyo_laser_scanner_2" />
    <axis xyz="0 0 1"/>
  </joint>

  <link name="xiaomi_pro_hub_motor_1">
    <visual>
      <origin xyz="0 0 0" rpy="0 0 0" />
      <geometry>
        <mesh filename="package://caato_description/meshes/xiaomi_pro_hub_motor.stl"/>
      </geometry>
      <material name="xiaomi_pro_hub_motor_material">
        <color rgba="0.101961 0.101961 0.101961 1.0"/>
      </material>
    </visual>
    <collision>
      <origin xyz="0 0 0" rpy="0 0 0" />
      <geometry>
        <mesh filename="package://caato_description/meshes/xiaomi_pro_hub_motor.stl"/>
      </geometry>
      <material name="xiaomi_pro_hub_motor_material">
        <color rgba="0.101961 0.101961 0.101961 1.0"/>
      </material>
    </collision>
    <inertial>
      <origin xyz="0 0 0" rpy="0 0 0" />
      <mass value="3.22716" />
      <inertia ixx="0.5091772" ixy="1.96248e-06"  ixz="-8.81136e-07" iyy="0.509018" iyz="4.58833e-07" izz="0.11918076" />
    </inertial>
  </link>

  <gazebo reference="xiaomi_pro_hub_motor_1">
    <mu1 value="100000.0"/>
    <mu2 value="100000.0"/>
    <kp value="10000000.0" />
    <kd value="1.0" />
    <fdir1 value="1 0 0"/>
    <material>Gazebo/Grey</material>
  </gazebo>

  <joint name="wheel_left_joint" type="continuous">
    <origin xyz="2.00861e-05 0.206425 -0.04955" rpy="0 -0 0" />
    <parent link="base_link" />
    <child link="xiaomi_pro_hub_motor_1" />
    <axis xyz="0 1 0" rpy="0 0 0" />
  </joint>

  <link name="xiaomi_pro_hub_motor_2">
    <visual>
      <origin xyz="0 0 0" rpy="0 0 0" />
      <geometry>
        <mesh filename="package://caato_description/meshes/xiaomi_pro_hub_motor.stl"/>
      </geometry>
      <material name="xiaomi_pro_hub_motor_material">
        <color rgba="0.101961 0.101961 0.101961 1.0"/>
      </material>
    </visual>
    <collision>
      <origin xyz="0 0 0" rpy="0 0 0" />
      <geometry>
        <mesh filename="package://caato_description/meshes/xiaomi_pro_hub_motor.stl"/>
      </geometry>
      <material name="xiaomi_pro_hub_motor_material">
        <color rgba="0.101961 0.101961 0.101961 1.0"/>
      </material>
    </collision>
    <inertial>
      <origin xyz="0 0 0" rpy="0 0 0" />
      <mass value="3.22716" />
      <inertia ixx="0.5091772" ixy="1.96248e-06"  ixz="-8.81136e-07" iyy="0.569018" iyz="4.58833e-07" izz="0.118076" />
    </inertial>
  </link>

  <gazebo reference="xiaomi_pro_hub_motor_2">
    <mu1 value="100000.0"/>
    <mu2 value="100000.0"/>
    <kp value="10000000.0" />
    <kd value="1.0" />
    <fdir1 value="1 0 0"/>
    <material>Gazebo/Grey</material>
  </gazebo>

  <joint name="wheel_right_joint" type="continuous">
    <origin xyz="0 -0.206425 -0.04955" rpy="0 0 0" />
    <parent link="base_link" />
    <child link="xiaomi_pro_hub_motor_2" />
    <axis xyz="0 1 0" rpy="0 0 0" />
  </joint>

  <!-- Caster wheels -->
  <link name="castor_wheel_mount_front" >
    <visual>
      <origin xyz="0 0 0" rpy="0 0 0" />
      <geometry>
        <mesh filename="package://caato_description/meshes/castor_mount.stl"/>
      </geometry>
      <material name="castor_mount_material">
        <color rgba="0.647059 0.647059 0.647059 1.0"/>
      </material>
    </visual>
    <collision>
      <origin xyz="0 0 0" rpy="0 0 0" />
      <geometry>
        <mesh filename="package://caato_description/meshes/castor_mount.stl"/>
      </geometry>
      <material name="castor_mount_material">
        <color rgba="0.647059 0.647059 0.647059 1.0"/>
      </material>
    </collision>
    <inertial>
      <origin xyz="0 0 0" rpy="0 0 0"/>
      <mass value="0.01" />
      <inertia ixx="0.001" ixy="0"  ixz="0" iyy="0.001" iyz="0" izz="0.001" />
    </inertial>
  </link>

  <gazebo reference="castor_wheel_mount_front" >
    <material>Gazebo/Grey</material>
  </gazebo>

  <joint name="castor_wheel_mount_front_joint"  type="fixed">
    <origin xyz="0.26 0 -0.0225" rpy="0 0 0" />
    <!-- <origin xyz="0.2981 0 &#45;0.10705" rpy="0 0 0" /> -->
    <parent link="base_link" />
    <child link="castor_wheel_mount_front" />
    <axis xyz="0 0 1"/>
  </joint>

  <link name="castor_wheel_front">
    <visual>
      <origin xyz="0 0 0" rpy="0 0 0" />
      <geometry>
        <mesh filename="package://caato_description/meshes/castor_wheel.stl"/>
      </geometry>
      <material name="castor_wheel_material">
        <color rgba="0.615686 0.811765 0.929412 1.0"/>
      </material>
    </visual>
    <collision>
      <origin xyz="0 0 0" rpy="0 0 0" />
      <geometry>
        <mesh filename="package://caato_description/meshes/castor_wheel.stl"/>
      </geometry>
      <material name="castor_wheel_material">
        <color rgba="0.615686 0.811765 0.929412 1.0"/>
      </material>
    </collision>
    <inertial>
      <origin xyz="0 0 0" rpy="0 0 0"/>
      <mass value="1" />
      <inertia ixx="0.09" ixy="0"  ixz="0" iyy="0.09" iyz="0" izz="0.15" />
    </inertial>
  </link>

  <joint name="castor_wheel_front_joint" type="continuous">
    <origin xyz="0.2981 0 -0.10705" rpy="0 0 0" />
    <parent link="base_link" />
    <child link="castor_wheel_front" />
    <axis xyz="0 1 0" rpy="0 0 0" />
  </joint>

  <gazebo reference="castor_wheel_front">
    <mu1 value="1.0"/>
    <mu2 value="1.0"/>
    <kp value="100000.0" />
    <kd value="1.0" />
    <fdir1 value="0 0 1"/>
    <material>Gazebo/Grey</material>
  </gazebo>

  <link name="castor_wheel_mount_back" >
    <visual>
      <origin xyz="0 0 0" rpy="0 0 0" />
      <geometry>
        <mesh filename="package://caato_description/meshes/castor_mount.stl"/>
      </geometry>
      <material name="castor_mount_material">
        <color rgba="0.647059 0.647059 0.647059 1.0"/>
      </material>
    </visual>
    <collision>
      <origin xyz="0.26 0 -0.0125" rpy="0 0 0" />
      <geometry>
        <mesh filename="package://caato_description/meshes/castor_mount.stl"/>
      </geometry>
      <material name="castor_mount_material">
        <color rgba="0.647059 0.647059 0.647059 1.0"/>
      </material>
    </collision>
    <inertial>
      <origin xyz="0 0 0" rpy="0 0 0"/>
      <mass value="0.01" />
      <inertia ixx="0.001" ixy="0"  ixz="0" iyy="0.001" iyz="0" izz="0.001" />
    </inertial>
  </link>

  <gazebo reference="castor_wheel_mount_back" >
    <material>Gazebo/Grey</material>
  </gazebo>

  <joint name="castor_wheel_mount_back_joint"  type="fixed">
    <origin xyz="-0.262 0 -0.0225" rpy="0 0 0" />
    <parent link="base_link" />
    <child link="castor_wheel_mount_back" />
    <axis xyz="0 0 1"/>
  </joint>

  <link name="castor_wheel_back">
    <visual>
      <origin xyz="0 0 0" rpy="0 0 0" />
      <geometry>
        <mesh filename="package://caato_description/meshes/castor_wheel.stl"/>
      </geometry>
      <material name="castor_wheel_material">
        <color rgba="0.615686 0.811765 0.929412 1.0"/>
      </material>
    </visual>
    <collision>
      <origin xyz="0 0 0" rpy="0 0 0" />
      <geometry>
        <mesh filename="package://caato_description/meshes/castor_wheel.stl"/>
      </geometry>
      <material name="castor_wheel_material">
        <color rgba="0.615686 0.811765 0.929412 1.0"/>
      </material>
    </collision>
    <inertial>
      <origin xyz="0 0 0" rpy="0 0 0"/>
      <mass value="1" />
      <inertia ixx="0.09" ixy="0"  ixz="0" iyy="0.09" iyz="0" izz="0.15" />
    </inertial>
  </link>

  <joint name="castor_wheel_back_joint" type="continuous">
    <origin xyz="-0.2219 0 -0.10705" rpy="0 1.46607 0" />
    <parent link="base_link" />
    <child link="castor_wheel_back" />
    <axis xyz="0 1 0" rpy="0 0 0" />
  </joint>

  <gazebo reference="castor_wheel_back">
    <mu1 value="1.0"/>
    <mu2 value="1.0"/>
    <kp value="100000.0" />
    <kd value="1.0" />
    <fdir1 value="0 0 1"/>
    <material>Gazebo/Grey</material>
  </gazebo>


  
  <joint name="camera_dummy_joint" type="fixed">
    <origin xyz="0.040 -0.000 0.90" rpy="0 0 0"/>
    <parent link="base_link"/>
    <child link="camera_dummy_link"/>
  </joint>

  <link name="camera_dummy_link">
    <visual>
      <geometry>
        <cylinder length="0.6" radius="0.02"/>
      </geometry>
      <material name="blue">
        <color rgba="0 0 .8 1"/>
      </material>
    </visual>
    <collision>
      <geometry>
        <cylinder length="0.6" radius="0.02"/>
      </geometry>
    </collision>
  </link>

  <joint name="camera_joint" type="fixed">
    <origin xyz="0.003 0.000 0.009" rpy="0 0 0"/>
    <parent link="camera_dummy_link"/>
    <child link="camera_frame"/>
  </joint>
  
  <link name="camera_frame"/>
  <joint name="camera_optical_joint" type="fixed">
    <origin xyz="0 0 0" rpy="-1.5707 0 -1.57"/>
    <parent link="camera_frame"/>
    <child link="camera_optical_frame"/>
  </joint>
  <link name="camera_optical_frame"/>


</robot>
