<?xml version="1.0"?>
<robot name="caato" xmlns:xacro="http://ros.org/wiki/xacro">
  <xacro:include filename="$(find caato_description)/urdf/caato.gazebo.xacro"/>
  <xacro:include filename="$(find realsense2_description)/urdf/_d435.urdf.xacro"/>

  <property name="base_height" value="0.02" /> 
  <property name="base_radius" value="0.4" /> 
  <property name="base_mass" value="5" /> <!-- in kg-->

  <property name="wheel_radius" value="0.16" /> 
  <property name="wheel_height" value="0.05" />
  <property name="wheel_mass" value="2.5" /> <!-- in kg-->

  <!-- caster wheel radius and height -->
  <!-- caster wheel mass -->
  <property name="caster_height" value="0.1" /> 
  <property name="caster_radius" value="0.03" /> 
  <property name="caster_mass" value="0.5" /> <!-- in kg-->

  <!-- Macro for calculating inertia of cylinder -->
  <macro name="cylinder_inertia" params="m r h">
    <inertia  ixx="${m*(3*r*r+h*h)/12}" ixy = "0" ixz = "0"
              iyy="${m*(3*r*r+h*h)/12}" iyz = "0"
              izz="${m*r*r/2}" /> 
  </macro>

  <link name="base_link">
    <visual>
      <origin xyz="0 0 0.0625" rpy="0 0 0" />
      <geometry>
        <mesh filename="package://caato_description/meshes/base_link.stl"/>
      </geometry>
      <material name="base_material">
        <color rgba="0.615686 0.811765 0.929412 1.0"/>
      </material>
    </visual>
    <collision>
      <origin xyz="0 0 0.0625" rpy="0 0 0" />
      <geometry>
        <mesh filename="package://caato_description/meshes/base_link.stl"/>
      </geometry>
      <material name="base_material">
        <color rgba="0.615686 0.811765 0.929412 1.0"/>
      </material>
    </collision>
    <inertial>
      <mass value="${base_mass}" />
      <origin xyz="0 0 0.0625" />
      <!--The 3x3 rotational inertia matrix. -->
      <cylinder_inertia  m="${base_mass}" r="${base_radius}" h="${base_height}" />
    </inertial> 
  </link>
  <gazebo reference="base_link">
    <material>Gazebo/DarkGrey</material>
  </gazebo>

  <link name="imu_link"/>
  <joint name="imu_joint" type="fixed">
    <origin xyz = "0 0 0.0625" rpy="0 0 0" />
    <parent link="base_link" />
    <child link="imu_link" />
  </joint>

  <link name="hokuyo_laser_scanner_1">
    <visual>
      <origin xyz="0 0 0" rpy="0 0 0" />
      <geometry>
        <mesh filename="package://caato_description/meshes/hokuyo_laser_scanner.stl"/>
      </geometry>
      <material name="hokuyo_laser_scanner_material">
        <color rgba="1 0.643137 0.0313725 1.0"/>
      </material>
    </visual>
    <collision>
      <origin xyz="0 0 0" rpy="0 0 0" />
      <geometry>
        <mesh filename="package://caato_description/meshes/hokuyo_laser_scanner.stl"/>
      </geometry>
      <material name="hokuyo_laser_scanner_material">
        <color rgba="1 0.643137 0.0313725 1.0"/>
      </material>
    </collision>
    <inertial>
      <origin xyz="0 0 0" rpy="0 0 0"/>
      <mass value="0.2" />
      <inertia ixx="0" ixy="0"  ixz="0" iyy="0" iyz="0" izz="0" />
    </inertial>
  </link>
  <gazebo reference="hokuyo_laser_scanner_1">
    <material>Gazebo/Orange</material>
  </gazebo>
  
  <joint name="hokuyo_laser_scanner_1_joint" type="fixed">
    <origin xyz="0.320104 0.330104 0.05225" rpy="3.14159 0 0.785398" />
    <parent link="base_link" />
    <child link="hokuyo_laser_scanner_1" />
    <axis xyz="0 0 1"/>
  </joint>

  <link name="hokuyo_laser_scanner_2">
    <visual>
      <origin xyz="0 0 0" rpy="0 0 0" />
      <geometry>
        <mesh filename="package://caato_description/meshes/hokuyo_laser_scanner.stl"/>
      </geometry>
      <material name="hokuyo_laser_scanner_material">
        <color rgba="1 0.643137 0.0313725 1.0"/>
      </material>
    </visual>
    <collision>
      <origin xyz="0 0 0" rpy="0 0 0" />
      <geometry>
        <mesh filename="package://caato_description/meshes/hokuyo_laser_scanner.stl"/>
      </geometry>
      <material name="hokuyo_laser_scanner_material">
        <color rgba="1 0.643137 0.0313725 1.0"/>
      </material>
    </collision>
    <inertial>
      <origin xyz="0 0 0" rpy="0 0 0"/>
      <mass value="0.2" />
      <inertia ixx="0" ixy="0"  ixz="0" iyy="0" iyz="0" izz="0" />
    </inertial>
  </link>

  <gazebo reference="hokuyo_laser_scanner_2">
    <material>Gazebo/Orange</material>
  </gazebo>

  <joint name="hokuyo_laser_scanner_2_joint" type="fixed">
    <origin xyz="-0.320104 -0.330104 0.0525" rpy="3.14159 0 -2.355" />
    <parent link="base_link" />
    <child link="hokuyo_laser_scanner_2" />
    <axis xyz="0 0 1"/>
  </joint>

  <link name="xiaomi_pro_hub_motor_1">
    <visual>
      <origin xyz="0 0 0" rpy="0 0 0" />
      <geometry>
        <mesh filename="package://caato_description/meshes/xiaomi_pro_hub_motor.stl"/>
      </geometry>
      <material name="xiaomi_pro_hub_motor_material">
        <color rgba="0.101961 0.101961 0.101961 1.0"/>
      </material>
    </visual>
    <collision>
      <origin xyz="0 0 0" rpy="0 0 0" />
      <geometry>
        <mesh filename="package://caato_description/meshes/xiaomi_pro_hub_motor.stl"/>
      </geometry>
      <material name="xiaomi_pro_hub_motor_material">
        <color rgba="0.101961 0.101961 0.101961 1.0"/>
      </material>
    </collision>
    <inertial>
      <mass value="${wheel_mass}" />
      <origin xyz="0 0 0" />
      <cylinder_inertia  m="${wheel_mass}" r="${wheel_radius}" h="${wheel_height}" />
    </inertial>
  </link>

  <gazebo reference="xiaomi_pro_hub_motor_1">
    <mu1 value="1.0"/>
    <mu2 value="1.0"/>
    <kp value="10000000.0" />
    <kd value="1.0" />
    <fdir1 value="1 0 0"/>
    <material>Gazebo/Grey</material>
  </gazebo>

  <joint name="wheel_left_joint" type="continuous">
    <origin xyz="2.00861e-05 0.206425 -0.04955" rpy="0 -0 0" />
    <parent link="base_link" />
    <child link="xiaomi_pro_hub_motor_1" />
    <axis xyz="0 1 0" rpy="0 0 0" />
  </joint>

  <link name="xiaomi_pro_hub_motor_2">
    <visual>
      <origin xyz="0 0 0" rpy="0 0 0" />
      <geometry>
        <mesh filename="package://caato_description/meshes/xiaomi_pro_hub_motor.stl"/>
      </geometry>
      <material name="xiaomi_pro_hub_motor_material">
        <color rgba="0.101961 0.101961 0.101961 1.0"/>
      </material>
    </visual>
    <collision>
      <origin xyz="0 0 0" rpy="0 0 0" />
      <geometry>
        <mesh filename="package://caato_description/meshes/xiaomi_pro_hub_motor.stl"/>
      </geometry>
      <material name="xiaomi_pro_hub_motor_material">
        <color rgba="0.101961 0.101961 0.101961 1.0"/>
      </material>
    </collision>
    <inertial>
      <mass value="${wheel_mass}" />
      <origin xyz="0 0 0" />
      <cylinder_inertia  m="${wheel_mass}" r="${wheel_radius}" h="${wheel_height}" />
    </inertial>
  </link>

  <gazebo reference="xiaomi_pro_hub_motor_2">
    <mu1 value="1.0"/>
    <mu2 value="1.0"/>
    <kp value="10000000.0" />
    <kd value="1.0" />
    <fdir1 value="1 0 0"/>
    <material>Gazebo/Grey</material>
  </gazebo>

  <joint name="wheel_right_joint" type="continuous">
    <origin xyz="0 -0.206425 -0.04955" rpy="0 0 0" />
    <parent link="base_link" />
    <child link="xiaomi_pro_hub_motor_2" />
    <axis xyz="0 1 0" rpy="0 0 0" />
  </joint>

  <!-- Caster wheels -->
  <link name="castor_wheel_mount_front" >
    <visual>
      <origin xyz="0 0 0" rpy="0 0 0" />
      <geometry>
        <mesh filename="package://caato_description/meshes/castor_mount.stl"/>
      </geometry>
      <material name="castor_mount_material">
        <color rgba="0.647059 0.647059 0.647059 1.0"/>
      </material>
    </visual>
    <collision>
      <origin xyz="0 0 0" rpy="0 0 0" />
      <geometry>
        <mesh filename="package://caato_description/meshes/castor_mount.stl"/>
      </geometry>
      <material name="castor_mount_material">
        <color rgba="0.647059 0.647059 0.647059 1.0"/>
      </material>
    </collision>
    <inertial>
      <origin xyz="0 0 0" rpy="0 0 0"/>
      <mass value="0.01" />
      <inertia ixx="0.001" ixy="0"  ixz="0" iyy="0.001" iyz="0" izz="0.001" />
    </inertial>
  </link>

  <gazebo reference="castor_wheel_mount_front" >
    <material>Gazebo/Grey</material>
  </gazebo>

  <joint name="castor_wheel_mount_front_joint"  type="fixed">
    <origin xyz="0.26 0 -0.0225" rpy="0 0 0" />
    <parent link="base_link" />
    <child link="castor_wheel_mount_front" />
    <axis xyz="0 0 1"/>
  </joint>

  <link name="castor_wheel_front">
    <visual>
      <origin xyz="0 0 0" rpy="0 0 0" />
      <geometry>
        <mesh filename="package://caato_description/meshes/castor_wheel.stl"/>
      </geometry>
      <material name="castor_wheel_material">
        <color rgba="0.615686 0.811765 0.929412 1.0"/>
      </material>
    </visual>
    <collision>
      <origin xyz="0 0 0" rpy="0 0 0" />
      <geometry>
        <mesh filename="package://caato_description/meshes/castor_wheel.stl"/>
      </geometry>
      <material name="castor_wheel_material">
        <color rgba="0.615686 0.811765 0.929412 1.0"/>
      </material>
    </collision>
    <inertial>
      <origin xyz="0 0 0" rpy="0 0 0"/>
      <mass value="${caster_mass}" />
      <inertia ixx="0.001" ixy="0"  ixz="0" iyy="0.001" iyz="0" izz="0.001" />
    </inertial>
  </link>

  <joint name="castor_wheel_front_joint" type="continuous">
    <origin xyz="0.2981 0 -0.10705" rpy="0 0 0" />
    <parent link="base_link" />
    <child link="castor_wheel_front" />
    <axis xyz="0 1 0" rpy="0 0 0" />
  </joint>

  <gazebo reference="castor_wheel_front">
    <mu1 value="1.0"/>
    <mu2 value="1.0"/>
    <kp value="100000.0" />
    <kd value="1.0" />
    <fdir1 value="0 0 1"/>
    <material>Gazebo/Grey</material>
  </gazebo>

  <link name="castor_wheel_mount_back" >
    <visual>
      <origin xyz="0 0 0" rpy="0 0 0" />
      <geometry>
        <mesh filename="package://caato_description/meshes/castor_mount.stl"/>
      </geometry>
      <material name="castor_mount_material">
        <color rgba="0.647059 0.647059 0.647059 1.0"/>
      </material>
    </visual>
    <collision>
      <origin xyz="0.26 0 -0.0125" rpy="0 0 0" />
      <geometry>
        <mesh filename="package://caato_description/meshes/castor_mount.stl"/>
      </geometry>
      <material name="castor_mount_material">
        <color rgba="0.647059 0.647059 0.647059 1.0"/>
      </material>
    </collision>
    <inertial>
      <origin xyz="0 0 0" rpy="0 0 0"/>
      <mass value="0.01" />
      <inertia ixx="0.001" ixy="0"  ixz="0" iyy="0.001" iyz="0" izz="0.001" />
    </inertial>
  </link>

  <gazebo reference="castor_wheel_mount_back" >
    <material>Gazebo/Grey</material>
  </gazebo>

  <joint name="castor_wheel_mount_back_joint"  type="fixed">
    <origin xyz="-0.262 0 -0.0225" rpy="0 0 0" />
    <parent link="base_link" />
    <child link="castor_wheel_mount_back" />
    <axis xyz="0 0 1"/>
  </joint>

  <link name="castor_wheel_back">
    <visual>
      <origin xyz="0 0 0" rpy="0 0 0" />
      <geometry>
        <mesh filename="package://caato_description/meshes/castor_wheel.stl"/>
      </geometry>
      <material name="castor_wheel_material">
        <color rgba="0.615686 0.811765 0.929412 1.0"/>
      </material>
    </visual>
    <collision>
      <origin xyz="0 0 0" rpy="0 0 0" />
      <geometry>
        <mesh filename="package://caato_description/meshes/castor_wheel.stl"/>
      </geometry>
      <material name="castor_wheel_material">
        <color rgba="0.615686 0.811765 0.929412 1.0"/>
      </material>
    </collision>
    <inertial>
      <origin xyz="0 0 0" rpy="0 0 0"/>
      <mass value="${caster_mass}" />
      <inertia ixx="0.001" ixy="0"  ixz="0" iyy="0.001" iyz="0" izz="0.001" />
    </inertial>
  </link>

  <joint name="castor_wheel_back_joint" type="continuous">
    <origin xyz="-0.2219 0 -0.10705" rpy="0 1.46607 0" />
    <parent link="base_link" />
    <child link="castor_wheel_back" />
    <axis xyz="0 1 0" rpy="0 0 0" />
  </joint>

  <gazebo reference="castor_wheel_back">
    <mu1 value="1.0"/>
    <mu2 value="1.0"/>
    <kp value="100000.0" />
    <kd value="1.0" />
    <fdir1 value="0 0 1"/>
    <material>Gazebo/Grey</material>
  </gazebo>

  <sensor_d435 parent="base_link">
    <origin xyz="0.35 0 0.38" rpy="0 0 0" />
  </sensor_d435>

  <!-- <xacro:include filename="$(find ouster_description)/urdf/OS1&#45;64.urdf.xacro"/> -->
  <!-- <OS1&#45;64 parent="base_link" name="os_sensor" hz="10" samples="220"> -->
  <!--   <origin xyz="0 0 1.2" rpy="0 0 0" /> -->
  <!-- </OS1&#45;64> -->

</robot>
