<?xml version="1.0" ?>
<robot name="caato_v1" xmlns:xacro="https://www.ros.org/wiki/xacro" >
	<xacro:arg name="botname" default=""/>

	<!-- Imports -->
	<xacro:include filename="$(find caato_description)/urdf/common_properties.xacro"/>
	<xacro:include filename="$(find caato_description)/urdf/caato_v1.gazebo.xacro" />
	<xacro:include filename="$(find caato_description)/urdf/macro.xacro" />

	<!-- Sensors -->
	<xacro:include filename="$(find realsense2_description)/urdf/_d435.2.urdf.xacro"/>
	<xacro:include filename="$(find realsense2_description)/urdf/_d435.gazebo.xacro"/>
	<xacro:sensor_d435 parent="base_link">
			<origin xyz="-0.302 0 0.357" rpy="0 0 3.14159" />
	</xacro:sensor_d435>
	
	<xacro:include filename="$(find caato_description)/urdf/dreamvue.xacro"/>

	<link name="base_link">
		<!-- pose and inertial -->
		<origin rpy="0 0 0" xyz="0 0 0.3337"/>

		<collision name="collision_chassis">
			<geometry>
				<mesh filename="package://caato_description/meshes/bases/caato_v1.stl"/>
				<!--<box size="0.454 0.354 0.173"/> -->
			</geometry>
		</collision>

		<visual>
			<!--<origin rpy="0 0 0" xyz="0 0 0.15"/>   -->
      <origin rpy="0 0 0" xyz="0 0 0"/>
      <geometry>
        <!-- <box size="0.454 0.354 0.173"/>  -->
				<mesh filename="package://caato_description/meshes/bases/caato_v1.stl"/>
			</geometry>
      <material name="blue"/>
    </visual>

		<collision name="caster_front_collision">
      <origin rpy="0 0 0" xyz="0.2108 0 -0.047"/>
      <geometry>
        <sphere radius="0.075"/>
      </geometry>
      <surface>
        <friction>
          <ode>
            <mu>0</mu>
            <mu2>0</mu2>
            <slip1>1.0</slip1>
            <slip2>1.0</slip2>
          </ode>
        </friction>
      </surface>
    </collision>
    
		<visual name="caster_front_visual">
      <origin rpy=" 0 0 4.71" xyz="0.2108 0 -0.047"/>
      <geometry>
	      <mesh filename="package://caato_description/meshes/wheels/front_caster_wheel.stl"/>
      </geometry>
    </visual>

		<collision name="caster_back_collision">
      <origin rpy="0 0 4.71" xyz="-0.3042 0 -0.0844"/>
      <geometry>
	      <mesh filename="package://caato_description/meshes/wheels/front_caster_wheel.stl"/>
        <!-- <sphere radius="0.070"/> -->
      </geometry>
      <surface>
        <friction>
          <ode>
            <mu>0</mu>
            <mu2>0</mu2>
            <slip1>1.0</slip1>
            <slip2>1.0</slip2>
          </ode>
        </friction>
      </surface>
    </collision>

		<visual name="caster_back_visual">
      <origin rpy="0 0 4.71" xyz="-0.3042 0 -0.0844"/>
      <geometry>
	  	<!-- <sphere radius="0.075"/> -->
	      <mesh filename="package://caato_description/meshes/wheels/rear_caster_wheel.stl"/>
			</geometry>
    </visual>
	
	</link>

	<link name="inertial_link" >
    <inertial>
      <mass value="50.0"/>
      <origin rpy="0 0 0" xyz="0 0 0"/> 
        <inertia ixx="0.329" ixy="0.003121" ixz="0.00227" iyy="0.314" iyz="0.00078" izz="0.422"/> 
        <!--inertia ixx="4806" ixy="-9.967" ixz="-119.983" iyy="5289" iyz="2.702" izz="2448"/-->
	      <!--inertia ixx="0.2" ixy="0" ixz="0" iyy="0.2" iyz="0" izz="0.296" /-->
    </inertial> 
  </link>

	<joint name="inertial_joint" type="fixed" >
    <orgin xyz="-0.095 0 0.1" rpy="0 0 0" />
    <parent link="base_link" />
    <child link="inertial_link" />
  </joint>

	<!-- Lider Sensor 1_Front -->
	<link name="hokuyo_laser_scanner_1">
		<visual>
			<origin xyz="0 0 0" rpy="0 0 0" />
			<geometry>
				<mesh filename="package://caato_description/meshes/sensors/hokuyo_laser_scanner.stl"/>
			</geometry>
			<material name="black"/>
		</visual>

		<collision>
			<origin xyz="0 0 0" rpy="0 0 0" />
			<geometry>
				<mesh filename="package://caato_description/meshes/sensors/hokuyo_laser_scanner.stl"/>
			</geometry>
			<material name="hokuyo_laser_scanner_material">
				<color rgba="1 0.643137 0.0313725 1.0"/>
			</material>
		</collision>
		
		<inertial>
			<origin xyz="0 0 0" rpy="0 0 0.785"/>
			<mass value="0.2" />
			<inertia ixx="0" ixy="0"  ixz="0" iyy="0" iyz="0" izz="0" />
		</inertial>
	</link>

	<joint name="hokuyo_laser_scanner_1_joint" type="fixed">
		<origin xyz="0.12 0.25 0.44" rpy="0 0 0.785" />
		<parent link="base_link" />
		<child link="hokuyo_laser_scanner_1" />
		<axis xyz="0 0 1"/>
	</joint>

	<!-- Lider Sensor 2_Back -->
	<link name="hokuyo_laser_scanner_2">
		<visual>
			<origin xyz="0 0 0" rpy="0 0 0" />
			<geometry>
				<mesh filename="package://caato_description/meshes/sensors/hokuyo_laser_scanner.stl"/>				
			</geometry>
			<material name="black"/>
		</visual>

		<collision>
			<origin xyz="0 0 0" rpy="0 0 0" />
			<geometry>
				<mesh filename="package://caato_description/meshes/sensors/hokuyo_laser_scanner.stl"/>				
			</geometry>
			<material name="hokuyo_laser_scanner_material">
				<color rgba="1 0.643137 0.0313725 1.0"/>
			</material>
		</collision>

		<inertial>
			<origin xyz="0 0 0" rpy="0 0 0"/>
			<mass value="0.2" />
			<inertia ixx="0" ixy="0"  ixz="0" iyy="0" iyz="0" izz="0" />
		</inertial>
	</link>

	<joint name="hokuyo_laser_scanner_2_joint" type="fixed">
		<origin xyz="-0.118 -0.25 0.44" rpy="0 0 -2.355" />
		<parent link="base_link" />
		<child link="hokuyo_laser_scanner_2" />
		<axis xyz="0 0 1"/>
	</joint>

	<!-- Right Wheel -->
	<link name="right_wheel">
		<inertial>
			<mass value="0.6"/>
			<origin xyz="0 0 0" rpy="0 0 0"/>
			<inertia ixx="0.001239" ixy="0" ixz="0.071" iyy="0.002336" iyz="0" izz="0.001237"/>
		</inertial>

		<collision name="right_wheel_collision">
			<origin xyz="0 0 0" rpy="0 0 0"/>
			<geometry>
				<cylinder length="0.04" radius="0.075"/>
			</geometry>
			<surface>
				<friction>
					<ode>
						<mu>1</mu>
						<mu2>1</mu2>
						<slip1>0.5</slip1>
						<slip2>0.5</slip2>
					</ode>
				</friction>
			</surface>
		</collision>

		<visual name="right_wheel_visual">
			<origin xyz="0 0 0" rpy="0 0 0"/>
			<geometry>
				<!-- <cylinder length="0.04" radius="0.075"/>  --> 
				<mesh filename="package://caato_description/meshes/wheels/drive_wheel.stl"/>
			</geometry>
		</visual>
	</link>
				
	<joint name="right_wheel_joint" type="continuous">
		<origin rpy="0 0 0" xyz="-0.15 0.24 -0.08"/>
		<child link="right_wheel"/>
		<parent link="base_link"/>
		<axis rpy="0 0 0" xyz="0 1 0"/>
		<limit effort="10000" velocity="1000"/>
		<joint_properties damping="1.0" friction="1.0"/>
	</joint>
		
	<!-- Left Wheel -->
	<link name="left_wheel">
		<inertial>
			<mass value="0.6"/>
			<origin xyz="0 0 0" rpy="0 0 0"/>
			<inertia ixx="0.001239" ixy="0" ixz="0.071" iyy="0.002336" iyz="0" izz="0.001237"/>
		</inertial>
		<collision name="left_wheel_collision">
			<origin xyz="0 0 0" rpy="0 0 0"/>
			<geometry>
				<cylinder length="0.04" radius="0.075"/>
			</geometry>
			<surface>
				<friction>
					<ode>
						<mu>1</mu>
						<mu2>1</mu2>
						<slip1>0.5</slip1>
						<slip2>0.5</slip2>
					</ode>
				</friction>
			</surface>
		</collision>
		<visual name="left_wheel_visual">
			<origin xyz="0 0 0" rpy="0 0 0"/>
			<geometry>
				<!-- <cylinder length="0.04" radius="0.075"/>  --> 
				<mesh filename="package://caato_description/meshes/wheels/drive_wheel.stl"/>
			</geometry>
		</visual>
	</link>      

	<joint name="left_wheel_joint" type="continuous">
		<origin rpy="0 1.5707 3.14" xyz="-0.15 -0.235 -0.08"/>
		<child link="left_wheel"/>
		<parent link="base_link"/>
		<axis rpy="0 0 0" xyz="0 1 0"/>
		<limit effort="10000" velocity="1000"/>
		<joint_properties damping="1.0" friction="1.0"/>
	</joint>

	<!-- Camera -->
	<joint name="camera_dummy_joint" type="fixed">
    <origin xyz="-0.351 -0.000 1.256" rpy="0 0 0"/>
    <parent link="base_link"/>
    <child link="camera_dummy_link"/>
  </joint>

  <link name="camera_dummy_link">
    <visual>
      <geometry>
        <cylinder length="0.6" radius="0.02"/>
      </geometry>
      <material name="blue">
        <color rgba="0 0 .8 1"/>
      </material>
    </visual>
    <collision>
      <geometry>
        <cylinder length="0.6" radius="0.02"/>
      </geometry>
    </collision>
  </link>

  <joint name="camera_joint" type="fixed">
    <origin xyz="0.003 0.000 0.009" rpy="0 0 0"/>
    <parent link="camera_dummy_link"/>
    <child link="camera_frame"/>
  </joint>
  
  <link name="camera_frame"/>
  <joint name="camera_optical_joint" type="fixed">
    <origin xyz="0 0 0" rpy="-1.5707 0 -1.57"/>
    <parent link="camera_frame"/>
    <child link="camera_optical_frame"/>
  </joint>
  <link name="camera_optical_frame"/>

</robot>