<?xml version="1.0" ?>
<robot name="caato_v1" xmlns:xacro="https://www.ros.org/wiki/xacro" >
	<xacro:arg name="botname" default=""/>

	<!-- Macro for calculating inertia of cylinder -->
	<xacro:macro name="cylinder_inertia" params="m r h">
		<inertia  ixx="${m*(3*r*r+h*h)/12}" ixy = "0" ixz = "0"
				iyy="${m*(3*r*r+h*h)/12}" iyz = "0"
				izz="${m*r*r/2}" /> 
	</xacro:macro>

    <!-- Imports -->
    <xacro:include filename="$(find caato_description)/urdf/common_properties.xacro"/>
    <xacro:include filename="$(find caato_description)/urdf/caato_v1f.gazebo.xacro" />
    <xacro:include filename="$(find caato_description)/urdf/macro.xacro" />

    <!-- sensors -->
    <xacro:include filename="$(find realsense2_description)/urdf/_d435.2.urdf.xacro"/>
    <xacro:include filename="$(find realsense2_description)/urdf/_d435.gazebo.xacro"/>
    <xacro:sensor_d435 parent="basemod_link">
        <origin xyz="-0.3 0 0.36" rpy="0 0 3.14159" />
    </xacro:sensor_d435>   
    
    <xacro:include filename="$(find realsense2_description)/urdf/_d435.front.urdf.xacro"/>
    <xacro:include filename="$(find realsense2_description)/urdf/_d435.front.gazebo.xacro"/>
    <xacro:d435_front parent="basemod_link">
        <origin xyz="0.12 0 0.35" rpy="0 0 0" />
    </xacro:d435_front> 
    
    <!-- Ouster -->    
    <xacro:include filename="$(find ouster_description)/urdf/OS1-64.urdf.xacro"/>
    <xacro:OS1-64 parent="basemod_link">
        <origin xyz="-0.2 0 1.37" rpy="0 0 0" />
    </xacro:OS1-64> 


	<link name="base_link">
	    <inertial>
	      <origin xyz="0.0 0.0 0.4" rpy="0 0 0"/>
	      <mass value="0"/>
	      <inertia
		ixx="0.0" ixy="0.0" ixz="0.0"
		iyy="0.0" iyz="0.0"
		izz="0.0"/>
	    </inertial>
	</link>

	<link name="inertial_link" >
		<inertial>
		<mass value="70.0"/>
		<origin rpy="0 0 0" xyz="0.1 0 0.05"/> 
			<inertia ixx="${50*(0.454*0.454+0.173*0.173)/12}"  ixy="0" ixz="0" iyy="${50*(0.37*0.37+0.173*0.173)/12}" iyz="0" izz="${50*(0.37*0.37+0.173*0.173)/12}"/>
		</inertial> 
 	</link>
	<joint name="inertial_joint" type="fixed" >
		<!-- values from CAD -->
		<!-- <origin xyz="-0.095 0 0.1" rpy="0 0 0" /> -->
		<!-- tested for simulation -->
		<origin xyz="-0.125 0 0" rpy="0 0 0" />
		<parent link="basemod_link" />
		<child link="inertial_link" />
  	</joint>
  	
  	
  	<link name="basemod_link" >	    
	    	<!-- pose and inertial -->
		<origin rpy="0 0 0" xyz="0.0 0 0.0"/>
		<collision name="collision_chassis">
			<geometry>
				<mesh filename="package://caato_description/meshes/bases/caato_v1.stl"/>
			</geometry>
		</collision>

		<visual>
      		<origin rpy="0 0 0" xyz="0.0 0 0.0"/>
      			<geometry>
				<mesh filename="package://caato_description/meshes/bases/caato_v1.stl"/>
			</geometry>
      		<material name="blue"/>
    		</visual>
 	</link>
	<joint name="basemod_joint" type="fixed" >
		<origin xyz="0.1175 0.0 0.0" rpy="0 0 0" />
		<parent link="base_link" />
		<child link="basemod_link" />
  	</joint>

	<link name="castor_front_link">
        <collision>
            <origin rpy="0 0 0" xyz="0 0 0"/>
            <geometry>
            	<!-- <sphere radius="0.075"/> -->
            	<mesh filename="package://caato_description/meshes/wheels/front_caster_wheel.stl"/>
            </geometry>
        </collision>	
        <visual>
            <origin rpy="0 0 0" xyz="0 0 0"/>
            <geometry>
            	<mesh filename="package://caato_description/meshes/wheels/front_caster_wheel.stl"/>
            </geometry>
        </visual>
    </link>
    
    
    <joint name="castor_front_joint" type="fixed" >
        <!--origin xyz="0.2108 0 -0.047" rpy="0 0 4.71" /-->
        <origin xyz="0.2108 0 -0.047" rpy="0 0 4.71" />
        <parent link="basemod_link" />
        <child link="castor_front_link" />
    </joint>

	<!-- Lider Sensor 1_Front -->
	<link name="hokuyo_laser_scanner_1">
		<visual>
			<origin xyz="0 0 0" rpy="0 0 0" />
			<geometry>
				<mesh filename="package://caato_description/meshes/sensors/hokuyo_laser_scanner.stl"/>
			</geometry>
			<material name="black"/>
		</visual>

		<collision>
			<origin xyz="0 0 0" rpy="0 0 0" />
			<geometry>
				<mesh filename="package://caato_description/meshes/sensors/hokuyo_laser_scanner.stl"/>
			</geometry>
			<material name="hokuyo_laser_scanner_material">
				<color rgba="1 0.643137 0.0313725 1.0"/>
			</material>
		</collision>
		
		<inertial>
			<origin xyz="0 0 0" rpy="0 0 0.785"/>
			<mass value="0.2" />
			<inertia ixx="0" ixy="0"  ixz="0" iyy="0" iyz="0" izz="0" />
		</inertial>
	</link>

	<joint name="hokuyo_laser_scanner_1_joint" type="fixed">
		<origin xyz="0.12 0.25 0.44" rpy="0 0 0.785" />
		<parent link="basemod_link" />
		<child link="hokuyo_laser_scanner_1" />
		<axis xyz="0 0 1"/>
	</joint>

	<!-- Lider Sensor 2_Back -->
	<link name="hokuyo_laser_scanner_2">
		<visual>
			<origin xyz="0 0 0" rpy="0 0 0" />
			<geometry>
				<mesh filename="package://caato_description/meshes/sensors/hokuyo_laser_scanner.stl"/>				
			</geometry>
			<material name="black"/>
		</visual>

		<collision>
			<origin xyz="0 0 0" rpy="0 0 0" />
			<geometry>
				<mesh filename="package://caato_description/meshes/sensors/hokuyo_laser_scanner.stl"/>				
			</geometry>
			<material name="hokuyo_laser_scanner_material">
				<color rgba="1 0.643137 0.0313725 1.0"/>
			</material>
		</collision>

		<inertial>
			<origin xyz="0 0 0" rpy="0 0 0"/>
			<mass value="0.2" />
			<inertia ixx="0" ixy="0"  ixz="0" iyy="0" iyz="0" izz="0" />
		</inertial>
	</link>

	<joint name="hokuyo_laser_scanner_2_joint" type="fixed">
		<origin xyz="-0.118 -0.25 0.44" rpy="0 0 -2.355" />
		<parent link="basemod_link" />
		<child link="hokuyo_laser_scanner_2" />
		<axis xyz="0 0 1"/>
	</joint>

	<!-- Right Wheel -->
	<link name="right_wheel_link">
        <inertial>
			<mass value="0.6"/>
			<origin xyz="0 0 0" rpy="1.5707 0 0"/>
			<xacro:cylinder_inertia m="0.6" r="0.075" h="0.04" />
			<!-- <inertia ixx="0.001239" ixy="0" ixz="0.071" iyy="0.002336" iyz="0" izz="0.001237"/> -->
        </inertial>
        <collision name="right_wheel_collision">
			<origin xyz="0 0 0" rpy="1.5707 0 0"/>
			<geometry>
				<cylinder length="0.04" radius="0.075"/>
				<!-- mesh filename="package://m2wr_description/meshes/Drive_wheel.stl"/ -->
			</geometry>
        </collision>
        <visual name="right_wheel_visual">
			<origin xyz="0 0 0" rpy="0 0 0"/>
			<geometry>
				<!-- <cylinder length="0.04" radius="0.075"/>   -->
				<mesh filename="package://caato_description/meshes/wheels/drive_wheel.stl"/>
			</geometry>
        </visual>
    </link>
				
    <joint name="right_wheel_joint" type="continuous">
        <origin rpy="0 0 0" xyz="-0.15 -0.235 -0.08"/>
        <child link="right_wheel_link"/>
        <parent link="basemod_link"/>
        <axis rpy="0 0 0" xyz="0 1 0"/>
        <limit effort="10000" velocity="1000"/>
		<dynamics damping="0" friction="1.0"/>
    </joint>
		
	<!-- Left Wheel -->
	<link name="left_wheel_link">
        <inertial>
			<mass value="0.6"/>
			<origin xyz="0 0 0" rpy="1.5707 0 0"/>
			<xacro:cylinder_inertia m="0.6" r="0.075" h="0.04" />
			<!-- <inertia ixx="0.001239" ixy="0" ixz="0.071" iyy="0.002336" iyz="0" izz="0.001237"/> -->
        </inertial>
        <collision name="left_wheel_collision">
			<origin xyz="0 0 0" rpy="1.5707 0 0"/>
			<geometry>
				<cylinder length="0.04" radius="0.075"/>
			</geometry>
        </collision>
        <visual name="left_wheel_visual">
			<origin xyz="0 0 0" rpy="3.14 0 0"/>
			<geometry>
				<!-- <cylinder length="0.04" radius="0.075"/>   -->
					<mesh filename="package://caato_description/meshes/wheels/drive_wheel.stl"/>
			</geometry>
        </visual>
    </link>     

    <joint name="left_wheel_joint" type="continuous">
        <!-- <origin rpy="0 1.5707 3.14" xyz="-0.15 -0.235 -0.08"/> -->
        <origin rpy="0 0 0" xyz="-0.15 0.235 -0.08"/>
        <child link="left_wheel_link"/>
        <parent link="basemod_link"/>
        <axis rpy="1.57 0 0" xyz="0 1 0"/>
        <limit effort="10000" velocity="1000"/>
		<dynamics damping="0.0" friction="1.0"/>
    </joint>
    
    
  
  <joint name="camera_dummy_joint" type="fixed">
    <origin xyz="-0.2 -0.000 1.23" rpy="0 0 0"/>
    <parent link="basemod_link"/>
    <child link="camera_dummy_link"/>
  </joint>

  <link name="camera_dummy_link">
		<visual>
			<origin xyz="0 0 0" rpy="0 0 0" />
			<geometry>
				<mesh filename="package://caato_description/meshes/sensors/pal.stl"/>				
			</geometry>
		</visual>
    <collision>
      <geometry>
        <cylinder length="0.02" radius="0.02"/>
      </geometry>
    </collision>
  </link>

  <joint name="camera_joint" type="fixed">
    <origin xyz="0.003 0.000 0.009" rpy="0 0 0"/>
    <parent link="camera_dummy_link"/>
    <child link="camera_frame"/>
  </joint>
  
  <link name="camera_frame"/>
  <joint name="camera_optical_joint" type="fixed">
    <origin xyz="0 0 0.1" rpy="-1.5707 0 -1.57"/>
    <parent link="camera_frame"/>
    <child link="camera_optical_frame"/>
  </joint>
  <link name="camera_optical_frame"/>
    
    
    
	<!-- Xnergy RCU -->
	<link name="xnergy_rcu_link">
		<visual>
			<origin xyz="0 0 0" rpy="0 0 0" />
			<geometry>
				<mesh filename="package://decada_sim_assets/models/Xnergy_RCU/meshes/Receiver-Unit.dae" scale="0.001 0.001 0.001"/>				
			</geometry>
		</visual>

		<collision>
			<origin xyz="0 0 0" rpy="0 0 0" />
			<geometry>
				<mesh filename="package://decada_sim_assets/models/Xnergy_RCU/meshes/Receiver-Unit.dae" scale="0.001 0.001 0.001"/>				
			</geometry>
		</collision>

		<inertial>
			<origin xyz="0 0 0" rpy="0 0 0"/>
			<mass value="0.2" />
			<inertia ixx="0" ixy="0"  ixz="0" iyy="0" iyz="0" izz="0" />
		</inertial>
	</link>

	<joint name="xnergy_rcu_joint" type="fixed">
		<origin xyz="0.35 0.12 0.2" rpy="0 1.5708 3.14159" />
		<parent link="basemod_link" />
		<child link="xnergy_rcu_link" />
		<axis xyz="0 0 1"/>
	</joint>   
	

    
</robot>
