<?xml version="1.0"?>
<robot xmlns:xacro="http://www.ros.org/wiki/xacro">
    <xacro:macro name="link_wheel" params="name">
        <link name="${name}">
            <inertial>
              <mass value="0.6"/>
              <origin rpy="0 1.5707 1.5707" xyz="0 0 0"/>
              <inertia ixx="0.001239" ixy="0" ixz="0.071" iyy="0.002336" iyz="0" izz="0.001237"/>
            </inertial>
            <collision name="link_right_wheel_collision">
              <origin rpy="0 1.5707 1.5707" xyz="0 0 0"/>
              <geometry>
                <cylinder length="0.04" radius="0.075"/>
              </geometry>
      <surface>
        <friction>
          <ode>
            <mu>1</mu>
            <mu2>1</mu2>
            <slip1>0.5</slip1>
            <slip2>0.5</slip2>
          </ode>
        </friction>
      </surface>
            </collision>
            <visual name="${name}_visual">
              <origin rpy="0 1.5707 1.5707" xyz="0 0 0"/>
              <geometry>
                <!-- <cylinder length="0.04" radius="0.075"/>  --> 
		<mesh filename="package://caato_description/meshes/wheels/drive_wheel.stl"/>
              </geometry>
            </visual>
        </link>
    </xacro:macro>

    <xacro:macro name="joint_wheel" params="name child origin_xyz">
      <joint name="${name}" type="continuous">
        <origin rpy="0 0 0" xyz="${origin_xyz}"/>
        <child link="${child}"/>
        <parent link="base_link"/>
        <axis rpy="0 0 0" xyz="0 1 0"/>
        <limit effort="10000" velocity="1000"/>
        <joint_properties damping="1.0" friction="1.0"/>
      </joint>
    </xacro:macro>

</robot>
